Workbook

Sheet README
A1: Chamberlain Apartments — Live TIF / Tax Appeal Model
A3: Built by KA Asset Management — May 2026
A4: Methodology source: Ehlers tax appeal analysis (published in Chamberlain TIF Update, 11/8/25)
A5: Contractual source: Recorded Minimum Assessment Agreement (Hennepin County T05543322, 6/18/2018)
A7: PURPOSE
A8: Live version of the TIF/tax appeal economics in the November 2025 Chamberlain Investment Overview (pp.13–14). User inputs a taxable market value (TMV) for each pay year 2026–2044 in the Inputs_TMV tab. The model recalculates Net Tax Capacity, Total Tax Increment Available, net TIF Note payment after Admin (10%) and OSA (0.36%) holdbacks, full TIF Note amortization at 4.60% interest against $7,142,377 principal, and gross property tax liability. Scenario_Compare runs three appeal targets side-by-side over the full 19-year TIF life — the correct horizon, vs. the 10-year truncation in the IDP/Shaver April 2026 model.
A10: CONVENTIONS
A11: • BLUE font on YELLOW fill = user input (change these freely)
A12: • BLACK font = formula (do not edit)
A13: • GREEN font = cross-sheet link
A15: TABS
A16: 1. README — this page
... A34: MAA Floor = $43,835,000 (legally enforceable assessed-value floor through TIF maturity)

Sheet Assumptions
A1: Assumptions & Constants
A3: TIF MECHANICS
A4: Class Rate (apartments) | B4: 0.0125 | C4: MN 273.13 — apartments above first $100K at 1.25%
A5: Tax Capacity Rate (composite local) | B5: 1.27866 | C5: Composite city + county + school + special, ties to Ehlers: 176,312 ÷ 137,888 = 1.2787 ≈ 1.28 (rounding to 1.2787 produces exact Ehlers match)
A6: Developer Share of Increment | B6: 1 | C6: TIF Plan §IV — Developer receives 90% of captured tax increment
A7: Admin Holdback % | B7: 0.1 | C7: Ehlers: "After admin (10%): Net annual developer reduction = –$158,681"
A8: OSA TIF Fee % | B8: 0.0036 | C8: State Auditor TIF fee; applied to TIF before developer share per Ehlers methodology
A9: Original Frozen Net Tax Capacity (Base) | B9: 37179 | C9: TIF "Original Tax Capacity" was frozen at project inception (pre-construction, very low); set to 0 for Ehlers-consistent simplification (marginal calc unaffected). Adjust if exact figure needed.
A11: TIF NOTE
A12: TIF Note Original Principal | B12: 7142377 | C12: TIF Note face; constant across scenarios per Investment Overview pg 14
A13: TIF Note Interest Rate | B13: 0.046 | C13: Per executed TIF Note; matches IDP model B15
A14: TIF Note Contractual Maturity | B14: 2/1/2046 | C14: Recorded TIF Note maturity (TIF terminates upon Note retirement OR maturity)
A15: Beginning Balance (Pay-2026 Start) | B15: 7269118.6 | C15: Per Shaver Inputs!B5 1/1/2026 starting balance (matches IDP model exactly so direct comparison is apples-to-apples)
A17: VALUATION INPUTS
A18: MAA Floor (recorded) | B18: 43835000 | C18: MAA §4: "shall not be less than $43,835,000 as of January 2, 2021... and each January 2 thereafter until termination" (Hennepin Co. T05543322)
A19: Pay 2025 TMV (1H) | B19: 54866000 | C19: 1H-2025 actual
A20: Pay 2025 TMV (2H) | B20: 52150000 | C20: 2H-2025 actual — County has already reduced
A21: Pay 2026 TMV (County preliminary) | B21: 52151000 | C21: Per Shaver MV History attachment row "2026: 52,151,000" — this is the 2026 starting point, NOT $54.866M
A23: EHLERS PUBLISHED RESULTS (anchors for reconciliation)
A24: Ehlers TMV reduction modeled | B24: 11031000 | C24: $54.866M baseline minus $43.835M MAA floor (full reduction to floor)
A25: Ehlers NTC reduction (annual) | B25: 137888 | C25: $11,031,000 × 1.25%
A26: Ehlers gross TIF reduction (annual) | B26: 176312 | C26: 137,888 NTC × 1.28
A27: Ehlers net TIF reduction after Admin | B27: 158681 | C27: $176,312 × 90% (developer share applied to admin haircut per Ehlers)
A28: Ehlers 18-yr cumulative tax savings | B28: 2856258 | C28: $158,681 × 18 yrs (approx) per Chamberlain TIF Update PDF p.1
A29: Ehlers lifetime TIF principal reduction | B29: -180329 | C29: Slower amortization impact
A30: Ehlers net nominal benefit | B30: 2675929 | C30: $2,856,258 minus $180,329 ≈ $2.68M
A31: Ehlers NPV @ 5% | B31: 1100000 | C31: Approximate, per Ehlers
A33: DISCOUNT RATE FOR NPV
A34: Discount Rate | B34: 0.05 | C34: Match Ehlers @ 5%. The IDP/Shaver model uses 8%, which understates TIF NPV by discounting at a higher rate than the TIF Note actually carries (4.60%).

Sheet Inputs_TMV
A1: Taxable Market Value Inputs by Scenario
A2: Edit YELLOW cells to change the TMV assumption for any year. Default values reflect: Current = $54.866M held flat (KA Nov-2025 baseline); Mid = $52.15M held flat (the IDP-claimed appeal target — note: County has already set 2026 at $52.151M); Aggressive = $50.0M held flat (KA Investment Overview pg 14 appeal scenario); plus a fourth column showing the Ehlers MAA-floor stress test at $43.835M.
A4: Pay Year | B4: Scenario 1: Current ($54.866M flat) | C4: Scenario 2: Mid Appeal ($52.15M flat) | D4: Scenario 3: Aggressive Appeal ($50.0M flat) | E4: Scenario 4: MAA Floor (Ehlers) ($43.835M flat)
A5: 2026 | B5: 54866000 | C5: 52150000 | D5: 50000000 | E5: 43835000
A6: 2027 | B6: 54866000 | C6: 52150000 | D6: 50000000 | E6: 43835000
A7: 2028 | B7: 54866000 | C7: 52150000 | D7: 50000000 | E7: 43835000
A8: 2029 | B8: 54866000 | C8: 52150000 | D8: 50000000 | E8: 43835000
A9: 2030 | B9: 54866000 | C9: 52150000 | D9: 50000000 | E9: 43835000
A10: 2031 | B10: 54866000 | C10: 52150000 | D10: 50000000 | E10: 43835000
A11: 2032 | B11: 54866000 | C11: 52150000 | D11: 50000000 | E11: 43835000
A12: 2033 | B12: 54866000 | C12: 52150000 | D12: 50000000 | E12: 43835000
A13: 2034 | B13: 54866000 | C13: 52150000 | D13: 50000000 | E13: 43835000
A14: 2035 | B14: 54866000 | C14: 52150000 | D14: 50000000 | E14: 43835000
A15: 2036 | B15: 54866000 | C15: 52150000 | D15: 50000000 | E15: 43835000
A16: 2037 | B16: 54866000 | C16: 52150000 | D16: 50000000 | E16: 43835000
... A23: 2044 | B23: 54866000 | C23: 52150000 | D23: 50000000 | E23: 43835000
A24: QUICK TESTS:
A25: • To replicate Shaver's stated scenario exactly (Mid Appeal): set ALL Mid Appeal cells (C5:C23) to $52,150,000. Engine_Mid_Appeal then shows the truth: even at flat $52.15M, net benefit vs. Current is $159K nominal / $101K NPV (positive, not negative).
A26: • To replicate KA Nov-2025 'Aggressive Appeal $50M' scenario: set ALL Aggressive cells (D5:D23) to $50,000,000. Engine_Agg_Appeal shows TIF payoff in 2042 (matches KA Nov-2025: 2/1/2044 within rounding) and net benefit of $285K nominal / $182K NPV.
A27: • To replicate Ehlers MAA-Floor stress test: set ALL MAA cells (E5:E23) to $43,835,000. Engine_MAA_Floor reproduces Ehlers' $158,681/yr net TIF reduction exactly (see Ehlers_Recon tab).
A28: • To test market growth: enter increasing TMVs by year (e.g., 2026=$50M, 2027=$51M, 2028=$52M, etc.). The model accepts any TMV schedule.
A29: • To test partial appeals (only some years successful): set Mid Appeal years 2026-2028 to $52.15M and 2029-2044 back to $54.866M. Model accounts for partial-period appeals.

Sheet Attorney_Fees
A1: Attorney Fees — Per Scenario
A2: IDP/Shaver applies a 25% fee to EVERY year of tax savings (overstates ~19x). MN contingency norm: 25% of FIRST-YEAR savings per successful petition. Set Pay Year for each appeal below — fees auto-compute per scenario based on each scenario's TMV reduction. To disable an appeal, clear its Pay Year cell.
A4: GLOBAL FEE PARAMETERS
A5: Contingency Fee % (of tax savings) | B5: 0.25
A6: Years of Savings per Appeal | B6: 1
A8: SCENARIO REFERENCE (TMVs from Inputs_TMV row 5)
A9: Scenario | B9: Reference TMV | C9: Annual Tax Savings vs. Current | D9: Fee per Appeal
A10: Current ($54.866M baseline) | B10: =Inputs_TMV!B5 -> 54866000 | C10: 0 | D10: 0
A11: Mid Appeal ($52.15M) | B11: =Inputs_TMV!C5 -> 52150000 | C11: =(B10-B11)*Assumptions!$B$4*Assumptions!$B$5 -> 43410.507 | D11: =C11*Attorney_Fees!$B$6*Attorney_Fees!$B$5 -> 10852.627
A12: Aggressive Appeal ($50.0M) | B12: =Inputs_TMV!D5 -> 50000000 | C12: =(B10-B12)*Assumptions!$B$4*Assumptions!$B$5 -> 77774.495 | D12: =C12*Attorney_Fees!$B$6*Attorney_Fees!$B$5 -> 19443.624
A13: MAA Floor ($43.835M) | B13: =Inputs_TMV!E5 -> 43835000 | C13: =(B10-B13)*Assumptions!$B$4*Assumptions!$B$5 -> 176311.23 | D13: =C13*Attorney_Fees!$B$6*Attorney_Fees!$B$5 -> 44077.808
A15: APPEAL EVENT SCHEDULE
A16: Appeal Event | B16: Pay Year | C16: Fee — Mid | D16: Fee — Agg | E16: Fee — MAA | F16: Disc Factor | G16: Notes
A17: Current Appeal | B17: 2026 | C17: =IF(AND(ISNUMBER(B17),B17>=2026,B17<=2044),Attorney_Fees!$D$11,0) -> 10852.627 | D17: =IF(AND(ISNUMBER(B17),B17>=2026,B17<=2044),Attorney_Fees!$D$12,0) -> 19443.624 | E17: =IF(AND(ISNUMBER(B17),B17>=2026,B17<=2044),Attorney_Fees!$D$13,0) -> 44077.808 | F17: =IF(ISNUMBER(B17),1/(1+Assumptions!$B$34)^(B17-2026),0) -> 1 | G17: In-flight 2025-pay-2026 petition
A18: 2nd Appeal | B18: 2030 | C18: =IF(AND(ISNUMBER(B18),B18>=2026,B18<=2044),Attorney_Fees!$D$11,0) -> 10852.627 | D18: =IF(AND(ISNUMBER(B18),B18>=2026,B18<=2044),Attorney_Fees!$D$12,0) -> 19443.624 | E18: =IF(AND(ISNUMBER(B18),B18>=2026,B18<=2044),Attorney_Fees!$D$13,0) -> 44077.808 | F18: =IF(ISNUMBER(B18),1/(1+Assumptions!$B$34)^(B18-2026),0) -> 0.82270247 | G18: Mid-hold reassessment
A19: 3rd Appeal | B19: 2036 | C19: =IF(AND(ISNUMBER(B19),B19>=2026,B19<=2044),Attorney_Fees!$D$11,0) -> 10852.627 | D19: =IF(AND(ISNUMBER(B19),B19>=2026,B19<=2044),Attorney_Fees!$D$12,0) -> 19443.624 | E19: =IF(AND(ISNUMBER(B19),B19>=2026,B19<=2044),Attorney_Fees!$D$13,0) -> 44077.808 | F19: =IF(ISNUMBER(B19),1/(1+Assumptions!$B$34)^(B19-2026),0) -> 0.61391325 | G19: Late-hold reassessment
A20: (custom) | C20: =IF(AND(ISNUMBER(B20),B20>=2026,B20<=2044),Attorney_Fees!$D$11,0) -> 0 | D20: =IF(AND(ISNUMBER(B20),B20>=2026,B20<=2044),Attorney_Fees!$D$12,0) -> 0 | E20: =IF(AND(ISNUMBER(B20),B20>=2026,B20<=2044),Attorney_Fees!$D$13,0) -> 0 | F20: =IF(ISNUMBER(B20),1/(1+Assumptions!$B$34)^(B20-2026),0) -> 0 | G20: Add events as needed
A21: (custom) | C21: =IF(AND(ISNUMBER(B21),B21>=2026,B21<=2044),Attorney_Fees!$D$11,0) -> 0 | D21: =IF(AND(ISNUMBER(B21),B21>=2026,B21<=2044),Attorney_Fees!$D$12,0) -> 0 | E21: =IF(AND(ISNUMBER(B21),B21>=2026,B21<=2044),Attorney_Fees!$D$13,0) -> 0 | F21: =IF(ISNUMBER(B21),1/(1+Assumptions!$B$34)^(B21-2026),0) -> 0
A23: TOTAL FEES BY SCENARIO
B24: Current | C24: Mid | D24: Agg | E24: MAA
A25: Total Fees — Nominal | B25: 0 | C25: =SUM(C17:C21) -> 32557.88 | D25: =SUM(D17:D21) -> 58330.871 | E25: =SUM(E17:E21) -> 132233.42
A26: Total Fees — NPV @ DiscRate | B26: 0 | C26: =SUMPRODUCT(C17:C21,F17:F21) -> 26443.681 | D26: =SUMPRODUCT(D17:D21,F17:F21) -> 47376.639 | E26: =SUMPRODUCT(E17:E21,F17:F21) -> 107400.68
A28: COMPARISON TO IDP/SHAVER FEE TREATMENT
A29: Shaver Cash Savings total fees (10-yr) | B29: 373694 | C29: Shaver Investor_Summary B12 — applied EVERY year of his 10-yr horizon
A30: This model — Agg, 3 appeals (default) | B30: =Attorney_Fees!$D$25 -> 58330.871 | C30: 3 events × 25% × first-year savings — only in appeal years
A31: Shaver overstates fees by | B31: =Attorney_Fees!$B$29-Attorney_Fees!$D$25 -> 315363.13 | C31: =Attorney_Fees!$B$29/Attorney_Fees!$D$25 -> 6.4064533 | D31: ← multiple
A33: KEY TAKEAWAY: Even applying the correct industry-standard fee structure (25% × first-year savings × 3 appeal events over 19 years), every appeal scenario remains net-positive on Scenario_Compare. Shaver's $373K fee is structurally wrong — it treats fees as recurring annual costs, not contingency events.

Sheet Engine_Current
A1: Engine — Scenario 1: Current ($54.866M flat)
A2: All TMV figures linked from Inputs_TMV tab. All constants linked from Assumptions tab. Methodology: Ehlers (Chamberlain TIF Update, 11/8/25).
A4: Pay Year | B4: TMV | C4: NTC | D4: Captured NTC | E4: Total Tax Increment | F4: Less OSA | G4: Less Admin | H4: Developer Share | I4: Net TIF to Developer | J4: Note Beg Bal | K4: Note Interest | L4: Note Principal Pmt | M4: Note End Bal | N4: Total Property Tax
B5: (input) | C5: TMV × ClassRate | D5: NTC − BaseNTC | E5: Captured × TaxCapRate | F5: × 0.36% | G5: × 10% | H5: × 90% | I5: TI × (1−OSA) × (1−Admin) × DevShare | K5: BegBal × 4.60% | L5: MIN(TIF − Int, Bal) | M5: Beg + Int − TIF (floored at 0) | N5: NTC × TaxCapRate (full burden)
A6: =Inputs_TMV!$A$5 -> 2026 | B6: =Inputs_TMV!$B$5 -> 54866000 | C6: =B6*Assumptions!$B$4 -> 685825 | D6: =MAX(C6-Assumptions!$B$9,0) -> 648646 | E6: =D6*Assumptions!$B$5 -> 829397.69 | F6: =E6*Assumptions!$B$8 -> 2985.8317 | G6: =(E6-F6)*Assumptions!$B$7 -> 82641.186 | H6: =(E6-F6-G6)*(1-Assumptions!$B$6) -> 0 | I6: =(E6-F6-G6)*Assumptions!$B$6 -> 743770.68 | J6: =Assumptions!$B$15 -> 7269118.6 | K6: =J6*Assumptions!$B$13 -> 334379.45 | L6: =MAX(0,MIN(I6-K6,J6)) -> 409391.22 | M6: =MAX(0,J6+K6-I6) -> 6859727.3 | N6: =C6*Assumptions!$B$5 -> 876936.99
A7: =Inputs_TMV!$A$6 -> 2027 | B7: =Inputs_TMV!$B$6 -> 54866000 | C7: =B7*Assumptions!$B$4 -> 685825 | D7: =MAX(C7-Assumptions!$B$9,0) -> 648646 | E7: =D7*Assumptions!$B$5 -> 829397.69 | F7: =E7*Assumptions!$B$8 -> 2985.8317 | G7: =(E7-F7)*Assumptions!$B$7 -> 82641.186 | H7: =(E7-F7-G7)*(1-Assumptions!$B$6) -> 0 | I7: =(E7-F7-G7)*Assumptions!$B$6 -> 743770.68 | J7: =M6 -> 6859727.3 | K7: =J7*Assumptions!$B$13 -> 315547.46 | L7: =MAX(0,MIN(I7-K7,J7)) -> 428223.22 | M7: =MAX(0,J7+K7-I7) -> 6431504.1 | N7: =C7*Assumptions!$B$5 -> 876936.99
A8: =Inputs_TMV!$A$7 -> 2028 | B8: =Inputs_TMV!$B$7 -> 54866000 | C8: =B8*Assumptions!$B$4 -> 685825 | D8: =MAX(C8-Assumptions!$B$9,0) -> 648646 | E8: =D8*Assumptions!$B$5 -> 829397.69 | F8: =E8*Assumptions!$B$8 -> 2985.8317 | G8: =(E8-F8)*Assumptions!$B$7 -> 82641.186 | H8: =(E8-F8-G8)*(1-Assumptions!$B$6) -> 0 | I8: =(E8-F8-G8)*Assumptions!$B$6 -> 743770.68 | J8: =M7 -> 6431504.1 | K8: =J8*Assumptions!$B$13 -> 295849.19 | L8: =MAX(0,MIN(I8-K8,J8)) -> 447921.49 | M8: =MAX(0,J8+K8-I8) -> 5983582.6 | N8: =C8*Assumptions!$B$5 -> 876936.99
A9: =Inputs_TMV!$A$8 -> 2029 | B9: =Inputs_TMV!$B$8 -> 54866000 | C9: =B9*Assumptions!$B$4 -> 685825 | D9: =MAX(C9-Assumptions!$B$9,0) -> 648646 | E9: =D9*Assumptions!$B$5 -> 829397.69 | F9: =E9*Assumptions!$B$8 -> 2985.8317 | G9: =(E9-F9)*Assumptions!$B$7 -> 82641.186 | H9: =(E9-F9-G9)*(1-Assumptions!$B$6) -> 0 | I9: =(E9-F9-G9)*Assumptions!$B$6 -> 743770.68 | J9: =M8 -> 5983582.6 | K9: =J9*Assumptions!$B$13 -> 275244.8 | L9: =MAX(0,MIN(I9-K9,J9)) -> 468525.87 | M9: =MAX(0,J9+K9-I9) -> 5515056.8 | N9: =C9*Assumptions!$B$5 -> 876936.99
A10: =Inputs_TMV!$A$9 -> 2030 | B10: =Inputs_TMV!$B$9 -> 54866000 | C10: =B10*Assumptions!$B$4 -> 685825 | D10: =MAX(C10-Assumptions!$B$9,0) -> 648646 | E10: =D10*Assumptions!$B$5 -> 829397.69 | F10: =E10*Assumptions!$B$8 -> 2985.8317 | G10: =(E10-F10)*Assumptions!$B$7 -> 82641.186 | H10: =(E10-F10-G10)*(1-Assumptions!$B$6) -> 0 | I10: =(E10-F10-G10)*Assumptions!$B$6 -> 743770.68 | J10: =M9 -> 5515056.8 | K10: =J10*Assumptions!$B$13 -> 253692.61 | L10: =MAX(0,MIN(I10-K10,J10)) -> 490078.07 | M10: =MAX(0,J10+K10-I10) -> 5024978.7 | N10: =C10*Assumptions!$B$5 -> 876936.99
A11: =Inputs_TMV!$A$10 -> 2031 | B11: =Inputs_TMV!$B$10 -> 54866000 | C11: =B11*Assumptions!$B$4 -> 685825 | D11: =MAX(C11-Assumptions!$B$9,0) -> 648646 | E11: =D11*Assumptions!$B$5 -> 829397.69 | F11: =E11*Assumptions!$B$8 -> 2985.8317 | G11: =(E11-F11)*Assumptions!$B$7 -> 82641.186 | H11: =(E11-F11-G11)*(1-Assumptions!$B$6) -> 0 | I11: =(E11-F11-G11)*Assumptions!$B$6 -> 743770.68 | J11: =M10 -> 5024978.7 | K11: =J11*Assumptions!$B$13 -> 231149.02 | L11: =MAX(0,MIN(I11-K11,J11)) -> 512621.66 | M11: =MAX(0,J11+K11-I11) -> 4512357 | N11: =C11*Assumptions!$B$5 -> 876936.99
A12: =Inputs_TMV!$A$11 -> 2032 | B12: =Inputs_TMV!$B$11 -> 54866000 | C12: =B12*Assumptions!$B$4 -> 685825 | D12: =MAX(C12-Assumptions!$B$9,0) -> 648646 | E12: =D12*Assumptions!$B$5 -> 829397.69 | F12: =E12*Assumptions!$B$8 -> 2985.8317 | G12: =(E12-F12)*Assumptions!$B$7 -> 82641.186 | H12: =(E12-F12-G12)*(1-Assumptions!$B$6) -> 0 | I12: =(E12-F12-G12)*Assumptions!$B$6 -> 743770.68 | J12: =M11 -> 4512357 | K12: =J12*Assumptions!$B$13 -> 207568.42 | L12: =MAX(0,MIN(I12-K12,J12)) -> 536202.25 | M12: =MAX(0,J12+K12-I12) -> 3976154.8 | N12: =C12*Assumptions!$B$5 -> 876936.99
A13: =Inputs_TMV!$A$12 -> 2033 | B13: =Inputs_TMV!$B$12 -> 54866000 | C13: =B13*Assumptions!$B$4 -> 685825 | D13: =MAX(C13-Assumptions!$B$9,0) -> 648646 | E13: =D13*Assumptions!$B$5 -> 829397.69 | F13: =E13*Assumptions!$B$8 -> 2985.8317 | G13: =(E13-F13)*Assumptions!$B$7 -> 82641.186 | H13: =(E13-F13-G13)*(1-Assumptions!$B$6) -> 0 | I13: =(E13-F13-G13)*Assumptions!$B$6 -> 743770.68 | J13: =M12 -> 3976154.8 | K13: =J13*Assumptions!$B$13 -> 182903.12 | L13: =MAX(0,MIN(I13-K13,J13)) -> 560867.56 | M13: =MAX(0,J13+K13-I13) -> 3415287.2 | N13: =C13*Assumptions!$B$5 -> 876936.99
A14: =Inputs_TMV!$A$13 -> 2034 | B14: =Inputs_TMV!$B$13 -> 54866000 | C14: =B14*Assumptions!$B$4 -> 685825 | D14: =MAX(C14-Assumptions!$B$9,0) -> 648646 | E14: =D14*Assumptions!$B$5 -> 829397.69 | F14: =E14*Assumptions!$B$8 -> 2985.8317 | G14: =(E14-F14)*Assumptions!$B$7 -> 82641.186 | H14: =(E14-F14-G14)*(1-Assumptions!$B$6) -> 0 | I14: =(E14-F14-G14)*Assumptions!$B$6 -> 743770.68 | J14: =M13 -> 3415287.2 | K14: =J14*Assumptions!$B$13 -> 157103.21 | L14: =MAX(0,MIN(I14-K14,J14)) -> 586667.46 | M14: =MAX(0,J14+K14-I14) -> 2828619.8 | N14: =C14*Assumptions!$B$5 -> 876936.99
A15: =Inputs_TMV!$A$14 -> 2035 | B15: =Inputs_TMV!$B$14 -> 54866000 | C15: =B15*Assumptions!$B$4 -> 685825 | D15: =MAX(C15-Assumptions!$B$9,0) -> 648646 | E15: =D15*Assumptions!$B$5 -> 829397.69 | F15: =E15*Assumptions!$B$8 -> 2985.8317 | G15: =(E15-F15)*Assumptions!$B$7 -> 82641.186 | H15: =(E15-F15-G15)*(1-Assumptions!$B$6) -> 0 | I15: =(E15-F15-G15)*Assumptions!$B$6 -> 743770.68 | J15: =M14 -> 2828619.8 | K15: =J15*Assumptions!$B$13 -> 130116.51 | L15: =MAX(0,MIN(I15-K15,J15)) -> 613654.17 | M15: =MAX(0,J15+K15-I15) -> 2214965.6 | N15: =C15*Assumptions!$B$5 -> 876936.99
A16: =Inputs_TMV!$A$15 -> 2036 | B16: =Inputs_TMV!$B$15 -> 54866000 | C16: =B16*Assumptions!$B$4 -> 685825 | D16: =MAX(C16-Assumptions!$B$9,0) -> 648646 | E16: =D16*Assumptions!$B$5 -> 829397.69 | F16: =E16*Assumptions!$B$8 -> 2985.8317 | G16: =(E16-F16)*Assumptions!$B$7 -> 82641.186 | H16: =(E16-F16-G16)*(1-Assumptions!$B$6) -> 0 | I16: =(E16-F16-G16)*Assumptions!$B$6 -> 743770.68 | J16: =M15 -> 2214965.6 | K16: =J16*Assumptions!$B$13 -> 101888.42 | L16: =MAX(0,MIN(I16-K16,J16)) -> 641882.26 | M16: =MAX(0,J16+K16-I16) -> 1573083.4 | N16: =C16*Assumptions!$B$5 -> 876936.99
A17: =Inputs_TMV!$A$16 -> 2037 | B17: =Inputs_TMV!$B$16 -> 54866000 | C17: =B17*Assumptions!$B$4 -> 685825 | D17: =MAX(C17-Assumptions!$B$9,0) -> 648646 | E17: =D17*Assumptions!$B$5 -> 829397.69 | F17: =E17*Assumptions!$B$8 -> 2985.8317 | G17: =(E17-F17)*Assumptions!$B$7 -> 82641.186 | H17: =(E17-F17-G17)*(1-Assumptions!$B$6) -> 0 | I17: =(E17-F17-G17)*Assumptions!$B$6 -> 743770.68 | J17: =M16 -> 1573083.4 | K17: =J17*Assumptions!$B$13 -> 72361.834 | L17: =MAX(0,MIN(I17-K17,J17)) -> 671408.84 | M17: =MAX(0,J17+K17-I17) -> 901674.51 | N17: =C17*Assumptions!$B$5 -> 876936.99
A18: =Inputs_TMV!$A$17 -> 2038 | B18: =Inputs_TMV!$B$17 -> 54866000 | C18: =B18*Assumptions!$B$4 -> 685825 | D18: =MAX(C18-Assumptions!$B$9,0) -> 648646 | E18: =D18*Assumptions!$B$5 -> 829397.69 | F18: =E18*Assumptions!$B$8 -> 2985.8317 | G18: =(E18-F18)*Assumptions!$B$7 -> 82641.186 | H18: =(E18-F18-G18)*(1-Assumptions!$B$6) -> 0 | I18: =(E18-F18-G18)*Assumptions!$B$6 -> 743770.68 | J18: =M17 -> 901674.51 | K18: =J18*Assumptions!$B$13 -> 41477.027 | L18: =MAX(0,MIN(I18-K18,J18)) -> 702293.65 | M18: =MAX(0,J18+K18-I18) -> 199380.86 | N18: =C18*Assumptions!$B$5 -> 876936.99
A19: =Inputs_TMV!$A$18 -> 2039 | B19: =Inputs_TMV!$B$18 -> 54866000 | C19: =B19*Assumptions!$B$4 -> 685825 | D19: =MAX(C19-Assumptions!$B$9,0) -> 648646 | E19: =D19*Assumptions!$B$5 -> 829397.69 | F19: =E19*Assumptions!$B$8 -> 2985.8317 | G19: =(E19-F19)*Assumptions!$B$7 -> 82641.186 | H19: =(E19-F19-G19)*(1-Assumptions!$B$6) -> 0 | I19: =(E19-F19-G19)*Assumptions!$B$6 -> 743770.68 | J19: =M18 -> 199380.86 | K19: =J19*Assumptions!$B$13 -> 9171.5195 | L19: =MAX(0,MIN(I19-K19,J19)) -> 199380.86 | M19: =MAX(0,J19+K19-I19) -> 0 | N19: =C19*Assumptions!$B$5 -> 876936.99
A20: =Inputs_TMV!$A$19 -> 2040 | B20: =Inputs_TMV!$B$19 -> 54866000 | C20: =B20*Assumptions!$B$4 -> 685825 | D20: =MAX(C20-Assumptions!$B$9,0) -> 648646 | E20: =D20*Assumptions!$B$5 -> 829397.69 | F20: =E20*Assumptions!$B$8 -> 2985.8317 | G20: =(E20-F20)*Assumptions!$B$7 -> 82641.186 | H20: =(E20-F20-G20)*(1-Assumptions!$B$6) -> 0 | I20: =(E20-F20-G20)*Assumptions!$B$6 -> 743770.68 | J20: =M19 -> 0 | K20: =J20*Assumptions!$B$13 -> 0 | L20: =MAX(0,MIN(I20-K20,J20)) -> 0 | M20: =MAX(0,J20+K20-I20) -> 0 | N20: =C20*Assumptions!$B$5 -> 876936.99
A21: =Inputs_TMV!$A$20 -> 2041 | B21: =Inputs_TMV!$B$20 -> 54866000 | C21: =B21*Assumptions!$B$4 -> 685825 | D21: =MAX(C21-Assumptions!$B$9,0) -> 648646 | E21: =D21*Assumptions!$B$5 -> 829397.69 | F21: =E21*Assumptions!$B$8 -> 2985.8317 | G21: =(E21-F21)*Assumptions!$B$7 -> 82641.186 | H21: =(E21-F21-G21)*(1-Assumptions!$B$6) -> 0 | I21: =(E21-F21-G21)*Assumptions!$B$6 -> 743770.68 | J21: =M20 -> 0 | K21: =J21*Assumptions!$B$13 -> 0 | L21: =MAX(0,MIN(I21-K21,J21)) -> 0 | M21: =MAX(0,J21+K21-I21) -> 0 | N21: =C21*Assumptions!$B$5 -> 876936.99
A22: =Inputs_TMV!$A$21 -> 2042 | B22: =Inputs_TMV!$B$21 -> 54866000 | C22: =B22*Assumptions!$B$4 -> 685825 | D22: =MAX(C22-Assumptions!$B$9,0) -> 648646 | E22: =D22*Assumptions!$B$5 -> 829397.69 | F22: =E22*Assumptions!$B$8 -> 2985.8317 | G22: =(E22-F22)*Assumptions!$B$7 -> 82641.186 | H22: =(E22-F22-G22)*(1-Assumptions!$B$6) -> 0 | I22: =(E22-F22-G22)*Assumptions!$B$6 -> 743770.68 | J22: =M21 -> 0 | K22: =J22*Assumptions!$B$13 -> 0 | L22: =MAX(0,MIN(I22-K22,J22)) -> 0 | M22: =MAX(0,J22+K22-I22) -> 0 | N22: =C22*Assumptions!$B$5 -> 876936.99
A23: =Inputs_TMV!$A$22 -> 2043 | B23: =Inputs_TMV!$B$22 -> 54866000 | C23: =B23*Assumptions!$B$4 -> 685825 | D23: =MAX(C23-Assumptions!$B$9,0) -> 648646 | E23: =D23*Assumptions!$B$5 -> 829397.69 | F23: =E23*Assumptions!$B$8 -> 2985.8317 | G23: =(E23-F23)*Assumptions!$B$7 -> 82641.186 | H23: =(E23-F23-G23)*(1-Assumptions!$B$6) -> 0 | I23: =(E23-F23-G23)*Assumptions!$B$6 -> 743770.68 | J23: =M22 -> 0 | K23: =J23*Assumptions!$B$13 -> 0 | L23: =MAX(0,MIN(I23-K23,J23)) -> 0 | M23: =MAX(0,J23+K23-I23) -> 0 | N23: =C23*Assumptions!$B$5 -> 876936.99
A24: =Inputs_TMV!$A$23 -> 2044 | B24: =Inputs_TMV!$B$23 -> 54866000 | C24: =B24*Assumptions!$B$4 -> 685825 | D24: =MAX(C24-Assumptions!$B$9,0) -> 648646 | E24: =D24*Assumptions!$B$5 -> 829397.69 | F24: =E24*Assumptions!$B$8 -> 2985.8317 | G24: =(E24-F24)*Assumptions!$B$7 -> 82641.186 | H24: =(E24-F24-G24)*(1-Assumptions!$B$6) -> 0 | I24: =(E24-F24-G24)*Assumptions!$B$6 -> 743770.68 | J24: =M23 -> 0 | K24: =J24*Assumptions!$B$13 -> 0 | L24: =MAX(0,MIN(I24-K24,J24)) -> 0 | M24: =MAX(0,J24+K24-I24) -> 0 | N24: =C24*Assumptions!$B$5 -> 876936.99
A25: Totals | C25: =SUM(C6:C24) -> 13030675 | D25: =SUM(D6:D24) -> 12324274 | E25: =SUM(E6:E24) -> 15758556 | F25: =SUM(F6:F24) -> 56730.802 | G25: =SUM(G6:G24) -> 1570182.5 | H25: =SUM(H6:H24) -> 0 | I25: =SUM(I6:I24) -> 14131643 | K25: =SUM(K6:K24) -> 2608452.6 | L25: =SUM(L6:L24) -> 7269118.6 | N25: =SUM(N6:N24) -> 16661803
A27: TIF Note Payoff Year: | B27: =IFERROR(INDEX(A6:A24,MATCH(TRUE(),M6:M24=0,0)),"Not paid off in horizon") -> 2039
A28: NPV @ DiscRate: | H28: NPV Net TIF: | I28: =NPV(Assumptions!$B$34,I6:I24) -> 8988707.3 | M28: NPV Prop Tax: | N28: =NPV(Assumptions!$B$34,N6:N24) -> 10598065

Sheet Engine_Mid_Appeal
A1: Engine — Scenario 2: Mid Appeal ($52.15M flat)
A2: All TMV figures linked from Inputs_TMV tab. All constants linked from Assumptions tab. Methodology: Ehlers (Chamberlain TIF Update, 11/8/25).
A4: Pay Year | B4: TMV | C4: NTC | D4: Captured NTC | E4: Total Tax Increment | F4: Less OSA | G4: Less Admin | H4: Developer Share | I4: Net TIF to Developer | J4: Note Beg Bal | K4: Note Interest | L4: Note Principal Pmt | M4: Note End Bal | N4: Total Property Tax
B5: (input) | C5: TMV × ClassRate | D5: NTC − BaseNTC | E5: Captured × TaxCapRate | F5: × 0.36% | G5: × 10% | H5: × 90% | I5: TI × (1−OSA) × (1−Admin) × DevShare | K5: BegBal × 4.60% | L5: MIN(TIF − Int, Bal) | M5: Beg + Int − TIF (floored at 0) | N5: NTC × TaxCapRate (full burden)
A6: =Inputs_TMV!$A$5 -> 2026 | B6: =Inputs_TMV!$C$5 -> 52150000 | C6: =B6*Assumptions!$B$4 -> 651875 | D6: =MAX(C6-Assumptions!$B$9,0) -> 614696 | E6: =D6*Assumptions!$B$5 -> 785987.19 | F6: =E6*Assumptions!$B$8 -> 2829.5539 | G6: =(E6-F6)*Assumptions!$B$7 -> 78315.763 | H6: =(E6-F6-G6)*(1-Assumptions!$B$6) -> 0 | I6: =(E6-F6-G6)*Assumptions!$B$6 -> 704841.87 | J6: =Assumptions!$B$15 -> 7269118.6 | K6: =J6*Assumptions!$B$13 -> 334379.45 | L6: =MAX(0,MIN(I6-K6,J6)) -> 370462.42 | M6: =MAX(0,J6+K6-I6) -> 6898656.2 | N6: =C6*Assumptions!$B$5 -> 833526.49
A7: =Inputs_TMV!$A$6 -> 2027 | B7: =Inputs_TMV!$C$6 -> 52150000 | C7: =B7*Assumptions!$B$4 -> 651875 | D7: =MAX(C7-Assumptions!$B$9,0) -> 614696 | E7: =D7*Assumptions!$B$5 -> 785987.19 | F7: =E7*Assumptions!$B$8 -> 2829.5539 | G7: =(E7-F7)*Assumptions!$B$7 -> 78315.763 | H7: =(E7-F7-G7)*(1-Assumptions!$B$6) -> 0 | I7: =(E7-F7-G7)*Assumptions!$B$6 -> 704841.87 | J7: =M6 -> 6898656.2 | K7: =J7*Assumptions!$B$13 -> 317338.18 | L7: =MAX(0,MIN(I7-K7,J7)) -> 387503.69 | M7: =MAX(0,J7+K7-I7) -> 6511152.5 | N7: =C7*Assumptions!$B$5 -> 833526.49
A8: =Inputs_TMV!$A$7 -> 2028 | B8: =Inputs_TMV!$C$7 -> 52150000 | C8: =B8*Assumptions!$B$4 -> 651875 | D8: =MAX(C8-Assumptions!$B$9,0) -> 614696 | E8: =D8*Assumptions!$B$5 -> 785987.19 | F8: =E8*Assumptions!$B$8 -> 2829.5539 | G8: =(E8-F8)*Assumptions!$B$7 -> 78315.763 | H8: =(E8-F8-G8)*(1-Assumptions!$B$6) -> 0 | I8: =(E8-F8-G8)*Assumptions!$B$6 -> 704841.87 | J8: =M7 -> 6511152.5 | K8: =J8*Assumptions!$B$13 -> 299513.01 | L8: =MAX(0,MIN(I8-K8,J8)) -> 405328.86 | M8: =MAX(0,J8+K8-I8) -> 6105823.6 | N8: =C8*Assumptions!$B$5 -> 833526.49
A9: =Inputs_TMV!$A$8 -> 2029 | B9: =Inputs_TMV!$C$8 -> 52150000 | C9: =B9*Assumptions!$B$4 -> 651875 | D9: =MAX(C9-Assumptions!$B$9,0) -> 614696 | E9: =D9*Assumptions!$B$5 -> 785987.19 | F9: =E9*Assumptions!$B$8 -> 2829.5539 | G9: =(E9-F9)*Assumptions!$B$7 -> 78315.763 | H9: =(E9-F9-G9)*(1-Assumptions!$B$6) -> 0 | I9: =(E9-F9-G9)*Assumptions!$B$6 -> 704841.87 | J9: =M8 -> 6105823.6 | K9: =J9*Assumptions!$B$13 -> 280867.89 | L9: =MAX(0,MIN(I9-K9,J9)) -> 423973.98 | M9: =MAX(0,J9+K9-I9) -> 5681849.6 | N9: =C9*Assumptions!$B$5 -> 833526.49
A10: =Inputs_TMV!$A$9 -> 2030 | B10: =Inputs_TMV!$C$9 -> 52150000 | C10: =B10*Assumptions!$B$4 -> 651875 | D10: =MAX(C10-Assumptions!$B$9,0) -> 614696 | E10: =D10*Assumptions!$B$5 -> 785987.19 | F10: =E10*Assumptions!$B$8 -> 2829.5539 | G10: =(E10-F10)*Assumptions!$B$7 -> 78315.763 | H10: =(E10-F10-G10)*(1-Assumptions!$B$6) -> 0 | I10: =(E10-F10-G10)*Assumptions!$B$6 -> 704841.87 | J10: =M9 -> 5681849.6 | K10: =J10*Assumptions!$B$13 -> 261365.08 | L10: =MAX(0,MIN(I10-K10,J10)) -> 443476.79 | M10: =MAX(0,J10+K10-I10) -> 5238372.8 | N10: =C10*Assumptions!$B$5 -> 833526.49
A11: =Inputs_TMV!$A$10 -> 2031 | B11: =Inputs_TMV!$C$10 -> 52150000 | C11: =B11*Assumptions!$B$4 -> 651875 | D11: =MAX(C11-Assumptions!$B$9,0) -> 614696 | E11: =D11*Assumptions!$B$5 -> 785987.19 | F11: =E11*Assumptions!$B$8 -> 2829.5539 | G11: =(E11-F11)*Assumptions!$B$7 -> 78315.763 | H11: =(E11-F11-G11)*(1-Assumptions!$B$6) -> 0 | I11: =(E11-F11-G11)*Assumptions!$B$6 -> 704841.87 | J11: =M10 -> 5238372.8 | K11: =J11*Assumptions!$B$13 -> 240965.15 | L11: =MAX(0,MIN(I11-K11,J11)) -> 463876.72 | M11: =MAX(0,J11+K11-I11) -> 4774496.1 | N11: =C11*Assumptions!$B$5 -> 833526.49
A12: =Inputs_TMV!$A$11 -> 2032 | B12: =Inputs_TMV!$C$11 -> 52150000 | C12: =B12*Assumptions!$B$4 -> 651875 | D12: =MAX(C12-Assumptions!$B$9,0) -> 614696 | E12: =D12*Assumptions!$B$5 -> 785987.19 | F12: =E12*Assumptions!$B$8 -> 2829.5539 | G12: =(E12-F12)*Assumptions!$B$7 -> 78315.763 | H12: =(E12-F12-G12)*(1-Assumptions!$B$6) -> 0 | I12: =(E12-F12-G12)*Assumptions!$B$6 -> 704841.87 | J12: =M11 -> 4774496.1 | K12: =J12*Assumptions!$B$13 -> 219626.82 | L12: =MAX(0,MIN(I12-K12,J12)) -> 485215.05 | M12: =MAX(0,J12+K12-I12) -> 4289281.1 | N12: =C12*Assumptions!$B$5 -> 833526.49
A13: =Inputs_TMV!$A$12 -> 2033 | B13: =Inputs_TMV!$C$12 -> 52150000 | C13: =B13*Assumptions!$B$4 -> 651875 | D13: =MAX(C13-Assumptions!$B$9,0) -> 614696 | E13: =D13*Assumptions!$B$5 -> 785987.19 | F13: =E13*Assumptions!$B$8 -> 2829.5539 | G13: =(E13-F13)*Assumptions!$B$7 -> 78315.763 | H13: =(E13-F13-G13)*(1-Assumptions!$B$6) -> 0 | I13: =(E13-F13-G13)*Assumptions!$B$6 -> 704841.87 | J13: =M12 -> 4289281.1 | K13: =J13*Assumptions!$B$13 -> 197306.93 | L13: =MAX(0,MIN(I13-K13,J13)) -> 507534.94 | M13: =MAX(0,J13+K13-I13) -> 3781746.1 | N13: =C13*Assumptions!$B$5 -> 833526.49
A14: =Inputs_TMV!$A$13 -> 2034 | B14: =Inputs_TMV!$C$13 -> 52150000 | C14: =B14*Assumptions!$B$4 -> 651875 | D14: =MAX(C14-Assumptions!$B$9,0) -> 614696 | E14: =D14*Assumptions!$B$5 -> 785987.19 | F14: =E14*Assumptions!$B$8 -> 2829.5539 | G14: =(E14-F14)*Assumptions!$B$7 -> 78315.763 | H14: =(E14-F14-G14)*(1-Assumptions!$B$6) -> 0 | I14: =(E14-F14-G14)*Assumptions!$B$6 -> 704841.87 | J14: =M13 -> 3781746.1 | K14: =J14*Assumptions!$B$13 -> 173960.32 | L14: =MAX(0,MIN(I14-K14,J14)) -> 530881.55 | M14: =MAX(0,J14+K14-I14) -> 3250864.6 | N14: =C14*Assumptions!$B$5 -> 833526.49
A15: =Inputs_TMV!$A$14 -> 2035 | B15: =Inputs_TMV!$C$14 -> 52150000 | C15: =B15*Assumptions!$B$4 -> 651875 | D15: =MAX(C15-Assumptions!$B$9,0) -> 614696 | E15: =D15*Assumptions!$B$5 -> 785987.19 | F15: =E15*Assumptions!$B$8 -> 2829.5539 | G15: =(E15-F15)*Assumptions!$B$7 -> 78315.763 | H15: =(E15-F15-G15)*(1-Assumptions!$B$6) -> 0 | I15: =(E15-F15-G15)*Assumptions!$B$6 -> 704841.87 | J15: =M14 -> 3250864.6 | K15: =J15*Assumptions!$B$13 -> 149539.77 | L15: =MAX(0,MIN(I15-K15,J15)) -> 555302.1 | M15: =MAX(0,J15+K15-I15) -> 2695562.5 | N15: =C15*Assumptions!$B$5 -> 833526.49
A16: =Inputs_TMV!$A$15 -> 2036 | B16: =Inputs_TMV!$C$15 -> 52150000 | C16: =B16*Assumptions!$B$4 -> 651875 | D16: =MAX(C16-Assumptions!$B$9,0) -> 614696 | E16: =D16*Assumptions!$B$5 -> 785987.19 | F16: =E16*Assumptions!$B$8 -> 2829.5539 | G16: =(E16-F16)*Assumptions!$B$7 -> 78315.763 | H16: =(E16-F16-G16)*(1-Assumptions!$B$6) -> 0 | I16: =(E16-F16-G16)*Assumptions!$B$6 -> 704841.87 | J16: =M15 -> 2695562.5 | K16: =J16*Assumptions!$B$13 -> 123995.87 | L16: =MAX(0,MIN(I16-K16,J16)) -> 580846 | M16: =MAX(0,J16+K16-I16) -> 2114716.5 | N16: =C16*Assumptions!$B$5 -> 833526.49
A17: =Inputs_TMV!$A$16 -> 2037 | B17: =Inputs_TMV!$C$16 -> 52150000 | C17: =B17*Assumptions!$B$4 -> 651875 | D17: =MAX(C17-Assumptions!$B$9,0) -> 614696 | E17: =D17*Assumptions!$B$5 -> 785987.19 | F17: =E17*Assumptions!$B$8 -> 2829.5539 | G17: =(E17-F17)*Assumptions!$B$7 -> 78315.763 | H17: =(E17-F17-G17)*(1-Assumptions!$B$6) -> 0 | I17: =(E17-F17-G17)*Assumptions!$B$6 -> 704841.87 | J17: =M16 -> 2114716.5 | K17: =J17*Assumptions!$B$13 -> 97276.958 | L17: =MAX(0,MIN(I17-K17,J17)) -> 607564.91 | M17: =MAX(0,J17+K17-I17) -> 1507151.6 | N17: =C17*Assumptions!$B$5 -> 833526.49
A18: =Inputs_TMV!$A$17 -> 2038 | B18: =Inputs_TMV!$C$17 -> 52150000 | C18: =B18*Assumptions!$B$4 -> 651875 | D18: =MAX(C18-Assumptions!$B$9,0) -> 614696 | E18: =D18*Assumptions!$B$5 -> 785987.19 | F18: =E18*Assumptions!$B$8 -> 2829.5539 | G18: =(E18-F18)*Assumptions!$B$7 -> 78315.763 | H18: =(E18-F18-G18)*(1-Assumptions!$B$6) -> 0 | I18: =(E18-F18-G18)*Assumptions!$B$6 -> 704841.87 | J18: =M17 -> 1507151.6 | K18: =J18*Assumptions!$B$13 -> 69328.972 | L18: =MAX(0,MIN(I18-K18,J18)) -> 635512.9 | M18: =MAX(0,J18+K18-I18) -> 871638.68 | N18: =C18*Assumptions!$B$5 -> 833526.49
A19: =Inputs_TMV!$A$18 -> 2039 | B19: =Inputs_TMV!$C$18 -> 52150000 | C19: =B19*Assumptions!$B$4 -> 651875 | D19: =MAX(C19-Assumptions!$B$9,0) -> 614696 | E19: =D19*Assumptions!$B$5 -> 785987.19 | F19: =E19*Assumptions!$B$8 -> 2829.5539 | G19: =(E19-F19)*Assumptions!$B$7 -> 78315.763 | H19: =(E19-F19-G19)*(1-Assumptions!$B$6) -> 0 | I19: =(E19-F19-G19)*Assumptions!$B$6 -> 704841.87 | J19: =M18 -> 871638.68 | K19: =J19*Assumptions!$B$13 -> 40095.379 | L19: =MAX(0,MIN(I19-K19,J19)) -> 664746.49 | M19: =MAX(0,J19+K19-I19) -> 206892.19 | N19: =C19*Assumptions!$B$5 -> 833526.49
A20: =Inputs_TMV!$A$19 -> 2040 | B20: =Inputs_TMV!$C$19 -> 52150000 | C20: =B20*Assumptions!$B$4 -> 651875 | D20: =MAX(C20-Assumptions!$B$9,0) -> 614696 | E20: =D20*Assumptions!$B$5 -> 785987.19 | F20: =E20*Assumptions!$B$8 -> 2829.5539 | G20: =(E20-F20)*Assumptions!$B$7 -> 78315.763 | H20: =(E20-F20-G20)*(1-Assumptions!$B$6) -> 0 | I20: =(E20-F20-G20)*Assumptions!$B$6 -> 704841.87 | J20: =M19 -> 206892.19 | K20: =J20*Assumptions!$B$13 -> 9517.0406 | L20: =MAX(0,MIN(I20-K20,J20)) -> 206892.19 | M20: =MAX(0,J20+K20-I20) -> 0 | N20: =C20*Assumptions!$B$5 -> 833526.49
A21: =Inputs_TMV!$A$20 -> 2041 | B21: =Inputs_TMV!$C$20 -> 52150000 | C21: =B21*Assumptions!$B$4 -> 651875 | D21: =MAX(C21-Assumptions!$B$9,0) -> 614696 | E21: =D21*Assumptions!$B$5 -> 785987.19 | F21: =E21*Assumptions!$B$8 -> 2829.5539 | G21: =(E21-F21)*Assumptions!$B$7 -> 78315.763 | H21: =(E21-F21-G21)*(1-Assumptions!$B$6) -> 0 | I21: =(E21-F21-G21)*Assumptions!$B$6 -> 704841.87 | J21: =M20 -> 0 | K21: =J21*Assumptions!$B$13 -> 0 | L21: =MAX(0,MIN(I21-K21,J21)) -> 0 | M21: =MAX(0,J21+K21-I21) -> 0 | N21: =C21*Assumptions!$B$5 -> 833526.49
A22: =Inputs_TMV!$A$21 -> 2042 | B22: =Inputs_TMV!$C$21 -> 52150000 | C22: =B22*Assumptions!$B$4 -> 651875 | D22: =MAX(C22-Assumptions!$B$9,0) -> 614696 | E22: =D22*Assumptions!$B$5 -> 785987.19 | F22: =E22*Assumptions!$B$8 -> 2829.5539 | G22: =(E22-F22)*Assumptions!$B$7 -> 78315.763 | H22: =(E22-F22-G22)*(1-Assumptions!$B$6) -> 0 | I22: =(E22-F22-G22)*Assumptions!$B$6 -> 704841.87 | J22: =M21 -> 0 | K22: =J22*Assumptions!$B$13 -> 0 | L22: =MAX(0,MIN(I22-K22,J22)) -> 0 | M22: =MAX(0,J22+K22-I22) -> 0 | N22: =C22*Assumptions!$B$5 -> 833526.49
A23: =Inputs_TMV!$A$22 -> 2043 | B23: =Inputs_TMV!$C$22 -> 52150000 | C23: =B23*Assumptions!$B$4 -> 651875 | D23: =MAX(C23-Assumptions!$B$9,0) -> 614696 | E23: =D23*Assumptions!$B$5 -> 785987.19 | F23: =E23*Assumptions!$B$8 -> 2829.5539 | G23: =(E23-F23)*Assumptions!$B$7 -> 78315.763 | H23: =(E23-F23-G23)*(1-Assumptions!$B$6) -> 0 | I23: =(E23-F23-G23)*Assumptions!$B$6 -> 704841.87 | J23: =M22 -> 0 | K23: =J23*Assumptions!$B$13 -> 0 | L23: =MAX(0,MIN(I23-K23,J23)) -> 0 | M23: =MAX(0,J23+K23-I23) -> 0 | N23: =C23*Assumptions!$B$5 -> 833526.49
A24: =Inputs_TMV!$A$23 -> 2044 | B24: =Inputs_TMV!$C$23 -> 52150000 | C24: =B24*Assumptions!$B$4 -> 651875 | D24: =MAX(C24-Assumptions!$B$9,0) -> 614696 | E24: =D24*Assumptions!$B$5 -> 785987.19 | F24: =E24*Assumptions!$B$8 -> 2829.5539 | G24: =(E24-F24)*Assumptions!$B$7 -> 78315.763 | H24: =(E24-F24-G24)*(1-Assumptions!$B$6) -> 0 | I24: =(E24-F24-G24)*Assumptions!$B$6 -> 704841.87 | J24: =M23 -> 0 | K24: =J24*Assumptions!$B$13 -> 0 | L24: =MAX(0,MIN(I24-K24,J24)) -> 0 | M24: =MAX(0,J24+K24-I24) -> 0 | N24: =C24*Assumptions!$B$5 -> 833526.49
A25: Totals | C25: =SUM(C6:C24) -> 12385625 | D25: =SUM(D6:D24) -> 11679224 | E25: =SUM(E6:E24) -> 14933757 | F25: =SUM(F6:F24) -> 53761.524 | G25: =SUM(G6:G24) -> 1487999.5 | H25: =SUM(H6:H24) -> 0 | I25: =SUM(I6:I24) -> 13391996 | K25: =SUM(K6:K24) -> 2815076.8 | L25: =SUM(L6:L24) -> 7269118.6 | N25: =SUM(N6:N24) -> 15837003
A27: TIF Note Payoff Year: | B27: =IFERROR(INDEX(A6:A24,MATCH(TRUE(),M6:M24=0,0)),"Not paid off in horizon") -> 2040
A28: NPV @ DiscRate: | H28: NPV Net TIF: | I28: =NPV(Assumptions!$B$34,I6:I24) -> 8518240.2 | M28: NPV Prop Tax: | N28: =NPV(Assumptions!$B$34,N6:N24) -> 10073435

Sheet Engine_Agg_Appeal
A1: Engine — Scenario 3: Aggressive Appeal ($50.0M flat)
A2: All TMV figures linked from Inputs_TMV tab. All constants linked from Assumptions tab. Methodology: Ehlers (Chamberlain TIF Update, 11/8/25).
A4: Pay Year | B4: TMV | C4: NTC | D4: Captured NTC | E4: Total Tax Increment | F4: Less OSA | G4: Less Admin | H4: Developer Share | I4: Net TIF to Developer | J4: Note Beg Bal | K4: Note Interest | L4: Note Principal Pmt | M4: Note End Bal | N4: Total Property Tax
B5: (input) | C5: TMV × ClassRate | D5: NTC − BaseNTC | E5: Captured × TaxCapRate | F5: × 0.36% | G5: × 10% | H5: × 90% | I5: TI × (1−OSA) × (1−Admin) × DevShare | K5: BegBal × 4.60% | L5: MIN(TIF − Int, Bal) | M5: Beg + Int − TIF (floored at 0) | N5: NTC × TaxCapRate (full burden)
A6: =Inputs_TMV!$A$5 -> 2026 | B6: =Inputs_TMV!$D$5 -> 50000000 | C6: =B6*Assumptions!$B$4 -> 625000 | D6: =MAX(C6-Assumptions!$B$9,0) -> 587821 | E6: =D6*Assumptions!$B$5 -> 751623.2 | F6: =E6*Assumptions!$B$8 -> 2705.8435 | G6: =(E6-F6)*Assumptions!$B$7 -> 74891.736 | H6: =(E6-F6-G6)*(1-Assumptions!$B$6) -> 0 | I6: =(E6-F6-G6)*Assumptions!$B$6 -> 674025.62 | J6: =Assumptions!$B$15 -> 7269118.6 | K6: =J6*Assumptions!$B$13 -> 334379.45 | L6: =MAX(0,MIN(I6-K6,J6)) -> 339646.17 | M6: =MAX(0,J6+K6-I6) -> 6929472.4 | N6: =C6*Assumptions!$B$5 -> 799162.5
A7: =Inputs_TMV!$A$6 -> 2027 | B7: =Inputs_TMV!$D$6 -> 50000000 | C7: =B7*Assumptions!$B$4 -> 625000 | D7: =MAX(C7-Assumptions!$B$9,0) -> 587821 | E7: =D7*Assumptions!$B$5 -> 751623.2 | F7: =E7*Assumptions!$B$8 -> 2705.8435 | G7: =(E7-F7)*Assumptions!$B$7 -> 74891.736 | H7: =(E7-F7-G7)*(1-Assumptions!$B$6) -> 0 | I7: =(E7-F7-G7)*Assumptions!$B$6 -> 674025.62 | J7: =M6 -> 6929472.4 | K7: =J7*Assumptions!$B$13 -> 318755.73 | L7: =MAX(0,MIN(I7-K7,J7)) -> 355269.89 | M7: =MAX(0,J7+K7-I7) -> 6574202.5 | N7: =C7*Assumptions!$B$5 -> 799162.5
A8: =Inputs_TMV!$A$7 -> 2028 | B8: =Inputs_TMV!$D$7 -> 50000000 | C8: =B8*Assumptions!$B$4 -> 625000 | D8: =MAX(C8-Assumptions!$B$9,0) -> 587821 | E8: =D8*Assumptions!$B$5 -> 751623.2 | F8: =E8*Assumptions!$B$8 -> 2705.8435 | G8: =(E8-F8)*Assumptions!$B$7 -> 74891.736 | H8: =(E8-F8-G8)*(1-Assumptions!$B$6) -> 0 | I8: =(E8-F8-G8)*Assumptions!$B$6 -> 674025.62 | J8: =M7 -> 6574202.5 | K8: =J8*Assumptions!$B$13 -> 302413.32 | L8: =MAX(0,MIN(I8-K8,J8)) -> 371612.31 | M8: =MAX(0,J8+K8-I8) -> 6202590.2 | N8: =C8*Assumptions!$B$5 -> 799162.5
A9: =Inputs_TMV!$A$8 -> 2029 | B9: =Inputs_TMV!$D$8 -> 50000000 | C9: =B9*Assumptions!$B$4 -> 625000 | D9: =MAX(C9-Assumptions!$B$9,0) -> 587821 | E9: =D9*Assumptions!$B$5 -> 751623.2 | F9: =E9*Assumptions!$B$8 -> 2705.8435 | G9: =(E9-F9)*Assumptions!$B$7 -> 74891.736 | H9: =(E9-F9-G9)*(1-Assumptions!$B$6) -> 0 | I9: =(E9-F9-G9)*Assumptions!$B$6 -> 674025.62 | J9: =M8 -> 6202590.2 | K9: =J9*Assumptions!$B$13 -> 285319.15 | L9: =MAX(0,MIN(I9-K9,J9)) -> 388706.47 | M9: =MAX(0,J9+K9-I9) -> 5813883.7 | N9: =C9*Assumptions!$B$5 -> 799162.5
A10: =Inputs_TMV!$A$9 -> 2030 | B10: =Inputs_TMV!$D$9 -> 50000000 | C10: =B10*Assumptions!$B$4 -> 625000 | D10: =MAX(C10-Assumptions!$B$9,0) -> 587821 | E10: =D10*Assumptions!$B$5 -> 751623.2 | F10: =E10*Assumptions!$B$8 -> 2705.8435 | G10: =(E10-F10)*Assumptions!$B$7 -> 74891.736 | H10: =(E10-F10-G10)*(1-Assumptions!$B$6) -> 0 | I10: =(E10-F10-G10)*Assumptions!$B$6 -> 674025.62 | J10: =M9 -> 5813883.7 | K10: =J10*Assumptions!$B$13 -> 267438.65 | L10: =MAX(0,MIN(I10-K10,J10)) -> 406586.97 | M10: =MAX(0,J10+K10-I10) -> 5407296.8 | N10: =C10*Assumptions!$B$5 -> 799162.5
A11: =Inputs_TMV!$A$10 -> 2031 | B11: =Inputs_TMV!$D$10 -> 50000000 | C11: =B11*Assumptions!$B$4 -> 625000 | D11: =MAX(C11-Assumptions!$B$9,0) -> 587821 | E11: =D11*Assumptions!$B$5 -> 751623.2 | F11: =E11*Assumptions!$B$8 -> 2705.8435 | G11: =(E11-F11)*Assumptions!$B$7 -> 74891.736 | H11: =(E11-F11-G11)*(1-Assumptions!$B$6) -> 0 | I11: =(E11-F11-G11)*Assumptions!$B$6 -> 674025.62 | J11: =M10 -> 5407296.8 | K11: =J11*Assumptions!$B$13 -> 248735.65 | L11: =MAX(0,MIN(I11-K11,J11)) -> 425289.97 | M11: =MAX(0,J11+K11-I11) -> 4982006.8 | N11: =C11*Assumptions!$B$5 -> 799162.5
A12: =Inputs_TMV!$A$11 -> 2032 | B12: =Inputs_TMV!$D$11 -> 50000000 | C12: =B12*Assumptions!$B$4 -> 625000 | D12: =MAX(C12-Assumptions!$B$9,0) -> 587821 | E12: =D12*Assumptions!$B$5 -> 751623.2 | F12: =E12*Assumptions!$B$8 -> 2705.8435 | G12: =(E12-F12)*Assumptions!$B$7 -> 74891.736 | H12: =(E12-F12-G12)*(1-Assumptions!$B$6) -> 0 | I12: =(E12-F12-G12)*Assumptions!$B$6 -> 674025.62 | J12: =M11 -> 4982006.8 | K12: =J12*Assumptions!$B$13 -> 229172.31 | L12: =MAX(0,MIN(I12-K12,J12)) -> 444853.31 | M12: =MAX(0,J12+K12-I12) -> 4537153.5 | N12: =C12*Assumptions!$B$5 -> 799162.5
A13: =Inputs_TMV!$A$12 -> 2033 | B13: =Inputs_TMV!$D$12 -> 50000000 | C13: =B13*Assumptions!$B$4 -> 625000 | D13: =MAX(C13-Assumptions!$B$9,0) -> 587821 | E13: =D13*Assumptions!$B$5 -> 751623.2 | F13: =E13*Assumptions!$B$8 -> 2705.8435 | G13: =(E13-F13)*Assumptions!$B$7 -> 74891.736 | H13: =(E13-F13-G13)*(1-Assumptions!$B$6) -> 0 | I13: =(E13-F13-G13)*Assumptions!$B$6 -> 674025.62 | J13: =M12 -> 4537153.5 | K13: =J13*Assumptions!$B$13 -> 208709.06 | L13: =MAX(0,MIN(I13-K13,J13)) -> 465316.56 | M13: =MAX(0,J13+K13-I13) -> 4071836.9 | N13: =C13*Assumptions!$B$5 -> 799162.5
A14: =Inputs_TMV!$A$13 -> 2034 | B14: =Inputs_TMV!$D$13 -> 50000000 | C14: =B14*Assumptions!$B$4 -> 625000 | D14: =MAX(C14-Assumptions!$B$9,0) -> 587821 | E14: =D14*Assumptions!$B$5 -> 751623.2 | F14: =E14*Assumptions!$B$8 -> 2705.8435 | G14: =(E14-F14)*Assumptions!$B$7 -> 74891.736 | H14: =(E14-F14-G14)*(1-Assumptions!$B$6) -> 0 | I14: =(E14-F14-G14)*Assumptions!$B$6 -> 674025.62 | J14: =M13 -> 4071836.9 | K14: =J14*Assumptions!$B$13 -> 187304.5 | L14: =MAX(0,MIN(I14-K14,J14)) -> 486721.12 | M14: =MAX(0,J14+K14-I14) -> 3585115.8 | N14: =C14*Assumptions!$B$5 -> 799162.5
A15: =Inputs_TMV!$A$14 -> 2035 | B15: =Inputs_TMV!$D$14 -> 50000000 | C15: =B15*Assumptions!$B$4 -> 625000 | D15: =MAX(C15-Assumptions!$B$9,0) -> 587821 | E15: =D15*Assumptions!$B$5 -> 751623.2 | F15: =E15*Assumptions!$B$8 -> 2705.8435 | G15: =(E15-F15)*Assumptions!$B$7 -> 74891.736 | H15: =(E15-F15-G15)*(1-Assumptions!$B$6) -> 0 | I15: =(E15-F15-G15)*Assumptions!$B$6 -> 674025.62 | J15: =M14 -> 3585115.8 | K15: =J15*Assumptions!$B$13 -> 164915.33 | L15: =MAX(0,MIN(I15-K15,J15)) -> 509110.29 | M15: =MAX(0,J15+K15-I15) -> 3076005.5 | N15: =C15*Assumptions!$B$5 -> 799162.5
A16: =Inputs_TMV!$A$15 -> 2036 | B16: =Inputs_TMV!$D$15 -> 50000000 | C16: =B16*Assumptions!$B$4 -> 625000 | D16: =MAX(C16-Assumptions!$B$9,0) -> 587821 | E16: =D16*Assumptions!$B$5 -> 751623.2 | F16: =E16*Assumptions!$B$8 -> 2705.8435 | G16: =(E16-F16)*Assumptions!$B$7 -> 74891.736 | H16: =(E16-F16-G16)*(1-Assumptions!$B$6) -> 0 | I16: =(E16-F16-G16)*Assumptions!$B$6 -> 674025.62 | J16: =M15 -> 3076005.5 | K16: =J16*Assumptions!$B$13 -> 141496.25 | L16: =MAX(0,MIN(I16-K16,J16)) -> 532529.37 | M16: =MAX(0,J16+K16-I16) -> 2543476.1 | N16: =C16*Assumptions!$B$5 -> 799162.5
A17: =Inputs_TMV!$A$16 -> 2037 | B17: =Inputs_TMV!$D$16 -> 50000000 | C17: =B17*Assumptions!$B$4 -> 625000 | D17: =MAX(C17-Assumptions!$B$9,0) -> 587821 | E17: =D17*Assumptions!$B$5 -> 751623.2 | F17: =E17*Assumptions!$B$8 -> 2705.8435 | G17: =(E17-F17)*Assumptions!$B$7 -> 74891.736 | H17: =(E17-F17-G17)*(1-Assumptions!$B$6) -> 0 | I17: =(E17-F17-G17)*Assumptions!$B$6 -> 674025.62 | J17: =M16 -> 2543476.1 | K17: =J17*Assumptions!$B$13 -> 116999.9 | L17: =MAX(0,MIN(I17-K17,J17)) -> 557025.72 | M17: =MAX(0,J17+K17-I17) -> 1986450.4 | N17: =C17*Assumptions!$B$5 -> 799162.5
A18: =Inputs_TMV!$A$17 -> 2038 | B18: =Inputs_TMV!$D$17 -> 50000000 | C18: =B18*Assumptions!$B$4 -> 625000 | D18: =MAX(C18-Assumptions!$B$9,0) -> 587821 | E18: =D18*Assumptions!$B$5 -> 751623.2 | F18: =E18*Assumptions!$B$8 -> 2705.8435 | G18: =(E18-F18)*Assumptions!$B$7 -> 74891.736 | H18: =(E18-F18-G18)*(1-Assumptions!$B$6) -> 0 | I18: =(E18-F18-G18)*Assumptions!$B$6 -> 674025.62 | J18: =M17 -> 1986450.4 | K18: =J18*Assumptions!$B$13 -> 91376.72 | L18: =MAX(0,MIN(I18-K18,J18)) -> 582648.9 | M18: =MAX(0,J18+K18-I18) -> 1403801.5 | N18: =C18*Assumptions!$B$5 -> 799162.5
A19: =Inputs_TMV!$A$18 -> 2039 | B19: =Inputs_TMV!$D$18 -> 50000000 | C19: =B19*Assumptions!$B$4 -> 625000 | D19: =MAX(C19-Assumptions!$B$9,0) -> 587821 | E19: =D19*Assumptions!$B$5 -> 751623.2 | F19: =E19*Assumptions!$B$8 -> 2705.8435 | G19: =(E19-F19)*Assumptions!$B$7 -> 74891.736 | H19: =(E19-F19-G19)*(1-Assumptions!$B$6) -> 0 | I19: =(E19-F19-G19)*Assumptions!$B$6 -> 674025.62 | J19: =M18 -> 1403801.5 | K19: =J19*Assumptions!$B$13 -> 64574.87 | L19: =MAX(0,MIN(I19-K19,J19)) -> 609450.75 | M19: =MAX(0,J19+K19-I19) -> 794350.78 | N19: =C19*Assumptions!$B$5 -> 799162.5
A20: =Inputs_TMV!$A$19 -> 2040 | B20: =Inputs_TMV!$D$19 -> 50000000 | C20: =B20*Assumptions!$B$4 -> 625000 | D20: =MAX(C20-Assumptions!$B$9,0) -> 587821 | E20: =D20*Assumptions!$B$5 -> 751623.2 | F20: =E20*Assumptions!$B$8 -> 2705.8435 | G20: =(E20-F20)*Assumptions!$B$7 -> 74891.736 | H20: =(E20-F20-G20)*(1-Assumptions!$B$6) -> 0 | I20: =(E20-F20-G20)*Assumptions!$B$6 -> 674025.62 | J20: =M19 -> 794350.78 | K20: =J20*Assumptions!$B$13 -> 36540.136 | L20: =MAX(0,MIN(I20-K20,J20)) -> 637485.48 | M20: =MAX(0,J20+K20-I20) -> 156865.29 | N20: =C20*Assumptions!$B$5 -> 799162.5
A21: =Inputs_TMV!$A$20 -> 2041 | B21: =Inputs_TMV!$D$20 -> 50000000 | C21: =B21*Assumptions!$B$4 -> 625000 | D21: =MAX(C21-Assumptions!$B$9,0) -> 587821 | E21: =D21*Assumptions!$B$5 -> 751623.2 | F21: =E21*Assumptions!$B$8 -> 2705.8435 | G21: =(E21-F21)*Assumptions!$B$7 -> 74891.736 | H21: =(E21-F21-G21)*(1-Assumptions!$B$6) -> 0 | I21: =(E21-F21-G21)*Assumptions!$B$6 -> 674025.62 | J21: =M20 -> 156865.29 | K21: =J21*Assumptions!$B$13 -> 7215.8036 | L21: =MAX(0,MIN(I21-K21,J21)) -> 156865.29 | M21: =MAX(0,J21+K21-I21) -> 0 | N21: =C21*Assumptions!$B$5 -> 799162.5
A22: =Inputs_TMV!$A$21 -> 2042 | B22: =Inputs_TMV!$D$21 -> 50000000 | C22: =B22*Assumptions!$B$4 -> 625000 | D22: =MAX(C22-Assumptions!$B$9,0) -> 587821 | E22: =D22*Assumptions!$B$5 -> 751623.2 | F22: =E22*Assumptions!$B$8 -> 2705.8435 | G22: =(E22-F22)*Assumptions!$B$7 -> 74891.736 | H22: =(E22-F22-G22)*(1-Assumptions!$B$6) -> 0 | I22: =(E22-F22-G22)*Assumptions!$B$6 -> 674025.62 | J22: =M21 -> 0 | K22: =J22*Assumptions!$B$13 -> 0 | L22: =MAX(0,MIN(I22-K22,J22)) -> 0 | M22: =MAX(0,J22+K22-I22) -> 0 | N22: =C22*Assumptions!$B$5 -> 799162.5
A23: =Inputs_TMV!$A$22 -> 2043 | B23: =Inputs_TMV!$D$22 -> 50000000 | C23: =B23*Assumptions!$B$4 -> 625000 | D23: =MAX(C23-Assumptions!$B$9,0) -> 587821 | E23: =D23*Assumptions!$B$5 -> 751623.2 | F23: =E23*Assumptions!$B$8 -> 2705.8435 | G23: =(E23-F23)*Assumptions!$B$7 -> 74891.736 | H23: =(E23-F23-G23)*(1-Assumptions!$B$6) -> 0 | I23: =(E23-F23-G23)*Assumptions!$B$6 -> 674025.62 | J23: =M22 -> 0 | K23: =J23*Assumptions!$B$13 -> 0 | L23: =MAX(0,MIN(I23-K23,J23)) -> 0 | M23: =MAX(0,J23+K23-I23) -> 0 | N23: =C23*Assumptions!$B$5 -> 799162.5
A24: =Inputs_TMV!$A$23 -> 2044 | B24: =Inputs_TMV!$D$23 -> 50000000 | C24: =B24*Assumptions!$B$4 -> 625000 | D24: =MAX(C24-Assumptions!$B$9,0) -> 587821 | E24: =D24*Assumptions!$B$5 -> 751623.2 | F24: =E24*Assumptions!$B$8 -> 2705.8435 | G24: =(E24-F24)*Assumptions!$B$7 -> 74891.736 | H24: =(E24-F24-G24)*(1-Assumptions!$B$6) -> 0 | I24: =(E24-F24-G24)*Assumptions!$B$6 -> 674025.62 | J24: =M23 -> 0 | K24: =J24*Assumptions!$B$13 -> 0 | L24: =MAX(0,MIN(I24-K24,J24)) -> 0 | M24: =MAX(0,J24+K24-I24) -> 0 | N24: =C24*Assumptions!$B$5 -> 799162.5
A25: Totals | C25: =SUM(C6:C24) -> 11875000 | D25: =SUM(D6:D24) -> 11168599 | E25: =SUM(E6:E24) -> 14280841 | F25: =SUM(F6:F24) -> 51411.027 | G25: =SUM(G6:G24) -> 1422943 | H25: =SUM(H6:H24) -> 0 | I25: =SUM(I6:I24) -> 12806487 | K25: =SUM(K6:K24) -> 3005346.8 | L25: =SUM(L6:L24) -> 7269118.6 | N25: =SUM(N6:N24) -> 15184088
A27: TIF Note Payoff Year: | B27: =IFERROR(INDEX(A6:A24,MATCH(TRUE(),M6:M24=0,0)),"Not paid off in horizon") -> 2041
A28: NPV @ DiscRate: | H28: NPV Net TIF: | I28: =NPV(Assumptions!$B$34,I6:I24) -> 8145815.9 | M28: NPV Prop Tax: | N28: =NPV(Assumptions!$B$34,N6:N24) -> 9658135.2

Sheet Engine_MAA_Floor
A1: Engine — Scenario 4: MAA Floor / Ehlers Stress ($43.835M flat)
A2: All TMV figures linked from Inputs_TMV tab. All constants linked from Assumptions tab. Methodology: Ehlers (Chamberlain TIF Update, 11/8/25).
A4: Pay Year | B4: TMV | C4: NTC | D4: Captured NTC | E4: Total Tax Increment | F4: Less OSA | G4: Less Admin | H4: Developer Share | I4: Net TIF to Developer | J4: Note Beg Bal | K4: Note Interest | L4: Note Principal Pmt | M4: Note End Bal | N4: Total Property Tax
B5: (input) | C5: TMV × ClassRate | D5: NTC − BaseNTC | E5: Captured × TaxCapRate | F5: × 0.36% | G5: × 10% | H5: × 90% | I5: TI × (1−OSA) × (1−Admin) × DevShare | K5: BegBal × 4.60% | L5: MIN(TIF − Int, Bal) | M5: Beg + Int − TIF (floored at 0) | N5: NTC × TaxCapRate (full burden)
A6: =Inputs_TMV!$A$5 -> 2026 | B6: =Inputs_TMV!$E$5 -> 43835000 | C6: =B6*Assumptions!$B$4 -> 547937.5 | D6: =MAX(C6-Assumptions!$B$9,0) -> 510758.5 | E6: =D6*Assumptions!$B$5 -> 653086.46 | F6: =E6*Assumptions!$B$8 -> 2351.1113 | G6: =(E6-F6)*Assumptions!$B$7 -> 65073.535 | H6: =(E6-F6-G6)*(1-Assumptions!$B$6) -> 0 | I6: =(E6-F6-G6)*Assumptions!$B$6 -> 585661.82 | J6: =Assumptions!$B$15 -> 7269118.6 | K6: =J6*Assumptions!$B$13 -> 334379.45 | L6: =MAX(0,MIN(I6-K6,J6)) -> 251282.36 | M6: =MAX(0,J6+K6-I6) -> 7017836.2 | N6: =C6*Assumptions!$B$5 -> 700625.76
A7: =Inputs_TMV!$A$6 -> 2027 | B7: =Inputs_TMV!$E$6 -> 43835000 | C7: =B7*Assumptions!$B$4 -> 547937.5 | D7: =MAX(C7-Assumptions!$B$9,0) -> 510758.5 | E7: =D7*Assumptions!$B$5 -> 653086.46 | F7: =E7*Assumptions!$B$8 -> 2351.1113 | G7: =(E7-F7)*Assumptions!$B$7 -> 65073.535 | H7: =(E7-F7-G7)*(1-Assumptions!$B$6) -> 0 | I7: =(E7-F7-G7)*Assumptions!$B$6 -> 585661.82 | J7: =M6 -> 7017836.2 | K7: =J7*Assumptions!$B$13 -> 322820.47 | L7: =MAX(0,MIN(I7-K7,J7)) -> 262841.35 | M7: =MAX(0,J7+K7-I7) -> 6754994.9 | N7: =C7*Assumptions!$B$5 -> 700625.76
A8: =Inputs_TMV!$A$7 -> 2028 | B8: =Inputs_TMV!$E$7 -> 43835000 | C8: =B8*Assumptions!$B$4 -> 547937.5 | D8: =MAX(C8-Assumptions!$B$9,0) -> 510758.5 | E8: =D8*Assumptions!$B$5 -> 653086.46 | F8: =E8*Assumptions!$B$8 -> 2351.1113 | G8: =(E8-F8)*Assumptions!$B$7 -> 65073.535 | H8: =(E8-F8-G8)*(1-Assumptions!$B$6) -> 0 | I8: =(E8-F8-G8)*Assumptions!$B$6 -> 585661.82 | J8: =M7 -> 6754994.9 | K8: =J8*Assumptions!$B$13 -> 310729.76 | L8: =MAX(0,MIN(I8-K8,J8)) -> 274932.05 | M8: =MAX(0,J8+K8-I8) -> 6480062.8 | N8: =C8*Assumptions!$B$5 -> 700625.76
A9: =Inputs_TMV!$A$8 -> 2029 | B9: =Inputs_TMV!$E$8 -> 43835000 | C9: =B9*Assumptions!$B$4 -> 547937.5 | D9: =MAX(C9-Assumptions!$B$9,0) -> 510758.5 | E9: =D9*Assumptions!$B$5 -> 653086.46 | F9: =E9*Assumptions!$B$8 -> 2351.1113 | G9: =(E9-F9)*Assumptions!$B$7 -> 65073.535 | H9: =(E9-F9-G9)*(1-Assumptions!$B$6) -> 0 | I9: =(E9-F9-G9)*Assumptions!$B$6 -> 585661.82 | J9: =M8 -> 6480062.8 | K9: =J9*Assumptions!$B$13 -> 298082.89 | L9: =MAX(0,MIN(I9-K9,J9)) -> 287578.93 | M9: =MAX(0,J9+K9-I9) -> 6192483.9 | N9: =C9*Assumptions!$B$5 -> 700625.76
A10: =Inputs_TMV!$A$9 -> 2030 | B10: =Inputs_TMV!$E$9 -> 43835000 | C10: =B10*Assumptions!$B$4 -> 547937.5 | D10: =MAX(C10-Assumptions!$B$9,0) -> 510758.5 | E10: =D10*Assumptions!$B$5 -> 653086.46 | F10: =E10*Assumptions!$B$8 -> 2351.1113 | G10: =(E10-F10)*Assumptions!$B$7 -> 65073.535 | H10: =(E10-F10-G10)*(1-Assumptions!$B$6) -> 0 | I10: =(E10-F10-G10)*Assumptions!$B$6 -> 585661.82 | J10: =M9 -> 6192483.9 | K10: =J10*Assumptions!$B$13 -> 284854.26 | L10: =MAX(0,MIN(I10-K10,J10)) -> 300807.56 | M10: =MAX(0,J10+K10-I10) -> 5891676.3 | N10: =C10*Assumptions!$B$5 -> 700625.76
A11: =Inputs_TMV!$A$10 -> 2031 | B11: =Inputs_TMV!$E$10 -> 43835000 | C11: =B11*Assumptions!$B$4 -> 547937.5 | D11: =MAX(C11-Assumptions!$B$9,0) -> 510758.5 | E11: =D11*Assumptions!$B$5 -> 653086.46 | F11: =E11*Assumptions!$B$8 -> 2351.1113 | G11: =(E11-F11)*Assumptions!$B$7 -> 65073.535 | H11: =(E11-F11-G11)*(1-Assumptions!$B$6) -> 0 | I11: =(E11-F11-G11)*Assumptions!$B$6 -> 585661.82 | J11: =M10 -> 5891676.3 | K11: =J11*Assumptions!$B$13 -> 271017.11 | L11: =MAX(0,MIN(I11-K11,J11)) -> 314644.71 | M11: =MAX(0,J11+K11-I11) -> 5577031.6 | N11: =C11*Assumptions!$B$5 -> 700625.76
A12: =Inputs_TMV!$A$11 -> 2032 | B12: =Inputs_TMV!$E$11 -> 43835000 | C12: =B12*Assumptions!$B$4 -> 547937.5 | D12: =MAX(C12-Assumptions!$B$9,0) -> 510758.5 | E12: =D12*Assumptions!$B$5 -> 653086.46 | F12: =E12*Assumptions!$B$8 -> 2351.1113 | G12: =(E12-F12)*Assumptions!$B$7 -> 65073.535 | H12: =(E12-F12-G12)*(1-Assumptions!$B$6) -> 0 | I12: =(E12-F12-G12)*Assumptions!$B$6 -> 585661.82 | J12: =M11 -> 5577031.6 | K12: =J12*Assumptions!$B$13 -> 256543.45 | L12: =MAX(0,MIN(I12-K12,J12)) -> 329118.36 | M12: =MAX(0,J12+K12-I12) -> 5247913.2 | N12: =C12*Assumptions!$B$5 -> 700625.76
A13: =Inputs_TMV!$A$12 -> 2033 | B13: =Inputs_TMV!$E$12 -> 43835000 | C13: =B13*Assumptions!$B$4 -> 547937.5 | D13: =MAX(C13-Assumptions!$B$9,0) -> 510758.5 | E13: =D13*Assumptions!$B$5 -> 653086.46 | F13: =E13*Assumptions!$B$8 -> 2351.1113 | G13: =(E13-F13)*Assumptions!$B$7 -> 65073.535 | H13: =(E13-F13-G13)*(1-Assumptions!$B$6) -> 0 | I13: =(E13-F13-G13)*Assumptions!$B$6 -> 585661.82 | J13: =M12 -> 5247913.2 | K13: =J13*Assumptions!$B$13 -> 241404.01 | L13: =MAX(0,MIN(I13-K13,J13)) -> 344257.81 | M13: =MAX(0,J13+K13-I13) -> 4903655.4 | N13: =C13*Assumptions!$B$5 -> 700625.76
A14: =Inputs_TMV!$A$13 -> 2034 | B14: =Inputs_TMV!$E$13 -> 43835000 | C14: =B14*Assumptions!$B$4 -> 547937.5 | D14: =MAX(C14-Assumptions!$B$9,0) -> 510758.5 | E14: =D14*Assumptions!$B$5 -> 653086.46 | F14: =E14*Assumptions!$B$8 -> 2351.1113 | G14: =(E14-F14)*Assumptions!$B$7 -> 65073.535 | H14: =(E14-F14-G14)*(1-Assumptions!$B$6) -> 0 | I14: =(E14-F14-G14)*Assumptions!$B$6 -> 585661.82 | J14: =M13 -> 4903655.4 | K14: =J14*Assumptions!$B$13 -> 225568.15 | L14: =MAX(0,MIN(I14-K14,J14)) -> 360093.67 | M14: =MAX(0,J14+K14-I14) -> 4543561.8 | N14: =C14*Assumptions!$B$5 -> 700625.76
A15: =Inputs_TMV!$A$14 -> 2035 | B15: =Inputs_TMV!$E$14 -> 43835000 | C15: =B15*Assumptions!$B$4 -> 547937.5 | D15: =MAX(C15-Assumptions!$B$9,0) -> 510758.5 | E15: =D15*Assumptions!$B$5 -> 653086.46 | F15: =E15*Assumptions!$B$8 -> 2351.1113 | G15: =(E15-F15)*Assumptions!$B$7 -> 65073.535 | H15: =(E15-F15-G15)*(1-Assumptions!$B$6) -> 0 | I15: =(E15-F15-G15)*Assumptions!$B$6 -> 585661.82 | J15: =M14 -> 4543561.8 | K15: =J15*Assumptions!$B$13 -> 209003.84 | L15: =MAX(0,MIN(I15-K15,J15)) -> 376657.98 | M15: =MAX(0,J15+K15-I15) -> 4166903.8 | N15: =C15*Assumptions!$B$5 -> 700625.76
A16: =Inputs_TMV!$A$15 -> 2036 | B16: =Inputs_TMV!$E$15 -> 43835000 | C16: =B16*Assumptions!$B$4 -> 547937.5 | D16: =MAX(C16-Assumptions!$B$9,0) -> 510758.5 | E16: =D16*Assumptions!$B$5 -> 653086.46 | F16: =E16*Assumptions!$B$8 -> 2351.1113 | G16: =(E16-F16)*Assumptions!$B$7 -> 65073.535 | H16: =(E16-F16-G16)*(1-Assumptions!$B$6) -> 0 | I16: =(E16-F16-G16)*Assumptions!$B$6 -> 585661.82 | J16: =M15 -> 4166903.8 | K16: =J16*Assumptions!$B$13 -> 191677.57 | L16: =MAX(0,MIN(I16-K16,J16)) -> 393984.24 | M16: =MAX(0,J16+K16-I16) -> 3772919.6 | N16: =C16*Assumptions!$B$5 -> 700625.76
A17: =Inputs_TMV!$A$16 -> 2037 | B17: =Inputs_TMV!$E$16 -> 43835000 | C17: =B17*Assumptions!$B$4 -> 547937.5 | D17: =MAX(C17-Assumptions!$B$9,0) -> 510758.5 | E17: =D17*Assumptions!$B$5 -> 653086.46 | F17: =E17*Assumptions!$B$8 -> 2351.1113 | G17: =(E17-F17)*Assumptions!$B$7 -> 65073.535 | H17: =(E17-F17-G17)*(1-Assumptions!$B$6) -> 0 | I17: =(E17-F17-G17)*Assumptions!$B$6 -> 585661.82 | J17: =M16 -> 3772919.6 | K17: =J17*Assumptions!$B$13 -> 173554.3 | L17: =MAX(0,MIN(I17-K17,J17)) -> 412107.52 | M17: =MAX(0,J17+K17-I17) -> 3360812 | N17: =C17*Assumptions!$B$5 -> 700625.76
A18: =Inputs_TMV!$A$17 -> 2038 | B18: =Inputs_TMV!$E$17 -> 43835000 | C18: =B18*Assumptions!$B$4 -> 547937.5 | D18: =MAX(C18-Assumptions!$B$9,0) -> 510758.5 | E18: =D18*Assumptions!$B$5 -> 653086.46 | F18: =E18*Assumptions!$B$8 -> 2351.1113 | G18: =(E18-F18)*Assumptions!$B$7 -> 65073.535 | H18: =(E18-F18-G18)*(1-Assumptions!$B$6) -> 0 | I18: =(E18-F18-G18)*Assumptions!$B$6 -> 585661.82 | J18: =M17 -> 3360812 | K18: =J18*Assumptions!$B$13 -> 154597.35 | L18: =MAX(0,MIN(I18-K18,J18)) -> 431064.46 | M18: =MAX(0,J18+K18-I18) -> 2929747.6 | N18: =C18*Assumptions!$B$5 -> 700625.76
A19: =Inputs_TMV!$A$18 -> 2039 | B19: =Inputs_TMV!$E$18 -> 43835000 | C19: =B19*Assumptions!$B$4 -> 547937.5 | D19: =MAX(C19-Assumptions!$B$9,0) -> 510758.5 | E19: =D19*Assumptions!$B$5 -> 653086.46 | F19: =E19*Assumptions!$B$8 -> 2351.1113 | G19: =(E19-F19)*Assumptions!$B$7 -> 65073.535 | H19: =(E19-F19-G19)*(1-Assumptions!$B$6) -> 0 | I19: =(E19-F19-G19)*Assumptions!$B$6 -> 585661.82 | J19: =M18 -> 2929747.6 | K19: =J19*Assumptions!$B$13 -> 134768.39 | L19: =MAX(0,MIN(I19-K19,J19)) -> 450893.43 | M19: =MAX(0,J19+K19-I19) -> 2478854.1 | N19: =C19*Assumptions!$B$5 -> 700625.76
A20: =Inputs_TMV!$A$19 -> 2040 | B20: =Inputs_TMV!$E$19 -> 43835000 | C20: =B20*Assumptions!$B$4 -> 547937.5 | D20: =MAX(C20-Assumptions!$B$9,0) -> 510758.5 | E20: =D20*Assumptions!$B$5 -> 653086.46 | F20: =E20*Assumptions!$B$8 -> 2351.1113 | G20: =(E20-F20)*Assumptions!$B$7 -> 65073.535 | H20: =(E20-F20-G20)*(1-Assumptions!$B$6) -> 0 | I20: =(E20-F20-G20)*Assumptions!$B$6 -> 585661.82 | J20: =M19 -> 2478854.1 | K20: =J20*Assumptions!$B$13 -> 114027.29 | L20: =MAX(0,MIN(I20-K20,J20)) -> 471634.53 | M20: =MAX(0,J20+K20-I20) -> 2007219.6 | N20: =C20*Assumptions!$B$5 -> 700625.76
A21: =Inputs_TMV!$A$20 -> 2041 | B21: =Inputs_TMV!$E$20 -> 43835000 | C21: =B21*Assumptions!$B$4 -> 547937.5 | D21: =MAX(C21-Assumptions!$B$9,0) -> 510758.5 | E21: =D21*Assumptions!$B$5 -> 653086.46 | F21: =E21*Assumptions!$B$8 -> 2351.1113 | G21: =(E21-F21)*Assumptions!$B$7 -> 65073.535 | H21: =(E21-F21-G21)*(1-Assumptions!$B$6) -> 0 | I21: =(E21-F21-G21)*Assumptions!$B$6 -> 585661.82 | J21: =M20 -> 2007219.6 | K21: =J21*Assumptions!$B$13 -> 92332.102 | L21: =MAX(0,MIN(I21-K21,J21)) -> 493329.71 | M21: =MAX(0,J21+K21-I21) -> 1513889.9 | N21: =C21*Assumptions!$B$5 -> 700625.76
A22: =Inputs_TMV!$A$21 -> 2042 | B22: =Inputs_TMV!$E$21 -> 43835000 | C22: =B22*Assumptions!$B$4 -> 547937.5 | D22: =MAX(C22-Assumptions!$B$9,0) -> 510758.5 | E22: =D22*Assumptions!$B$5 -> 653086.46 | F22: =E22*Assumptions!$B$8 -> 2351.1113 | G22: =(E22-F22)*Assumptions!$B$7 -> 65073.535 | H22: =(E22-F22-G22)*(1-Assumptions!$B$6) -> 0 | I22: =(E22-F22-G22)*Assumptions!$B$6 -> 585661.82 | J22: =M21 -> 1513889.9 | K22: =J22*Assumptions!$B$13 -> 69638.935 | L22: =MAX(0,MIN(I22-K22,J22)) -> 516022.88 | M22: =MAX(0,J22+K22-I22) -> 997867.02 | N22: =C22*Assumptions!$B$5 -> 700625.76
A23: =Inputs_TMV!$A$22 -> 2043 | B23: =Inputs_TMV!$E$22 -> 43835000 | C23: =B23*Assumptions!$B$4 -> 547937.5 | D23: =MAX(C23-Assumptions!$B$9,0) -> 510758.5 | E23: =D23*Assumptions!$B$5 -> 653086.46 | F23: =E23*Assumptions!$B$8 -> 2351.1113 | G23: =(E23-F23)*Assumptions!$B$7 -> 65073.535 | H23: =(E23-F23-G23)*(1-Assumptions!$B$6) -> 0 | I23: =(E23-F23-G23)*Assumptions!$B$6 -> 585661.82 | J23: =M22 -> 997867.02 | K23: =J23*Assumptions!$B$13 -> 45901.883 | L23: =MAX(0,MIN(I23-K23,J23)) -> 539759.93 | M23: =MAX(0,J23+K23-I23) -> 458107.08 | N23: =C23*Assumptions!$B$5 -> 700625.76
A24: =Inputs_TMV!$A$23 -> 2044 | B24: =Inputs_TMV!$E$23 -> 43835000 | C24: =B24*Assumptions!$B$4 -> 547937.5 | D24: =MAX(C24-Assumptions!$B$9,0) -> 510758.5 | E24: =D24*Assumptions!$B$5 -> 653086.46 | F24: =E24*Assumptions!$B$8 -> 2351.1113 | G24: =(E24-F24)*Assumptions!$B$7 -> 65073.535 | H24: =(E24-F24-G24)*(1-Assumptions!$B$6) -> 0 | I24: =(E24-F24-G24)*Assumptions!$B$6 -> 585661.82 | J24: =M23 -> 458107.08 | K24: =J24*Assumptions!$B$13 -> 21072.926 | L24: =MAX(0,MIN(I24-K24,J24)) -> 458107.08 | M24: =MAX(0,J24+K24-I24) -> 0 | N24: =C24*Assumptions!$B$5 -> 700625.76
A25: Totals | C25: =SUM(C6:C24) -> 10410812 | D25: =SUM(D6:D24) -> 9704411.5 | E25: =SUM(E6:E24) -> 12408643 | F25: =SUM(F6:F24) -> 44671.114 | G25: =SUM(G6:G24) -> 1236397.2 | H25: =SUM(H6:H24) -> 0 | I25: =SUM(I6:I24) -> 11127575 | K25: =SUM(K6:K24) -> 3751974.1 | L25: =SUM(L6:L24) -> 7269118.6 | N25: =SUM(N6:N24) -> 13311890
A27: TIF Note Payoff Year: | B27: =IFERROR(INDEX(A6:A24,MATCH(TRUE(),M6:M24=0,0)),"Not paid off in horizon") -> 2044
